
2020-05-25 11:23:46,143 INFO: errors [in app.py:464]
2020-05-25 11:25:16,246 INFO: errors [in app.py:464]
2020-05-25 11:25:27,743 ERROR: Exception on /shows [GET] [in /Library/Frameworks/Python.framework/Versions/3.7/lib/python3.7/site-packages/flask/app.py:1892]
Traceback (most recent call last):
  File "/Library/Frameworks/Python.framework/Versions/3.7/lib/python3.7/site-packages/sqlalchemy/util/_collections.py", line 1030, in __call__
    return self.registry[key]
KeyError: 123145501327360

During handling of the above exception, another exception occurred:

Traceback (most recent call last):
  File "/Library/Frameworks/Python.framework/Versions/3.7/lib/python3.7/site-packages/flask/app.py", line 2447, in wsgi_app
    response = self.full_dispatch_request()
  File "/Library/Frameworks/Python.framework/Versions/3.7/lib/python3.7/site-packages/flask/app.py", line 1952, in full_dispatch_request
    rv = self.handle_user_exception(e)
  File "/Library/Frameworks/Python.framework/Versions/3.7/lib/python3.7/site-packages/flask/app.py", line 1821, in handle_user_exception
    reraise(exc_type, exc_value, tb)
  File "/Library/Frameworks/Python.framework/Versions/3.7/lib/python3.7/site-packages/flask/_compat.py", line 39, in reraise
    raise value
  File "/Library/Frameworks/Python.framework/Versions/3.7/lib/python3.7/site-packages/flask/app.py", line 1950, in full_dispatch_request
    rv = self.dispatch_request()
  File "/Library/Frameworks/Python.framework/Versions/3.7/lib/python3.7/site-packages/flask/app.py", line 1936, in dispatch_request
    return self.view_functions[rule.endpoint](**req.view_args)
  File "app.py", line 410, in shows
    shows = Show.query.all()
  File "/Library/Frameworks/Python.framework/Versions/3.7/lib/python3.7/site-packages/flask_sqlalchemy/__init__.py", line 519, in __get__
    return type.query_class(mapper, session=self.sa.session())
  File "/Library/Frameworks/Python.framework/Versions/3.7/lib/python3.7/site-packages/sqlalchemy/orm/scoping.py", line 78, in __call__
    return self.registry()
  File "/Library/Frameworks/Python.framework/Versions/3.7/lib/python3.7/site-packages/sqlalchemy/util/_collections.py", line 1032, in __call__
    return self.registry.setdefault(key, self.createfunc())
  File "/Library/Frameworks/Python.framework/Versions/3.7/lib/python3.7/site-packages/sqlalchemy/orm/session.py", line 3254, in __call__
    return self.class_(**local_kw)
  File "/Library/Frameworks/Python.framework/Versions/3.7/lib/python3.7/site-packages/flask_sqlalchemy/__init__.py", line 138, in __init__
    bind = options.pop('bind', None) or db.engine
  File "/Library/Frameworks/Python.framework/Versions/3.7/lib/python3.7/site-packages/flask_sqlalchemy/__init__.py", line 937, in engine
    return self.get_engine()
  File "/Library/Frameworks/Python.framework/Versions/3.7/lib/python3.7/site-packages/flask_sqlalchemy/__init__.py", line 956, in get_engine
    return connector.get_engine()
  File "/Library/Frameworks/Python.framework/Versions/3.7/lib/python3.7/site-packages/flask_sqlalchemy/__init__.py", line 560, in get_engine
    options = self.get_options(sa_url, echo)
  File "/Library/Frameworks/Python.framework/Versions/3.7/lib/python3.7/site-packages/flask_sqlalchemy/__init__.py", line 575, in get_options
    self._sa.apply_driver_hacks(self._app, sa_url, options)
  File "/Library/Frameworks/Python.framework/Versions/3.7/lib/python3.7/site-packages/flask_sqlalchemy/__init__.py", line 877, in apply_driver_hacks
    if sa_url.drivername.startswith('mysql'):
AttributeError: 'NoneType' object has no attribute 'drivername'
2020-05-25 11:25:29,183 ERROR: Exception on /artists [GET] [in /Library/Frameworks/Python.framework/Versions/3.7/lib/python3.7/site-packages/flask/app.py:1892]
Traceback (most recent call last):
  File "/Library/Frameworks/Python.framework/Versions/3.7/lib/python3.7/site-packages/sqlalchemy/util/_collections.py", line 1030, in __call__
    return self.registry[key]
KeyError: 123145506582528

During handling of the above exception, another exception occurred:

Traceback (most recent call last):
  File "/Library/Frameworks/Python.framework/Versions/3.7/lib/python3.7/site-packages/flask/app.py", line 2447, in wsgi_app
    response = self.full_dispatch_request()
  File "/Library/Frameworks/Python.framework/Versions/3.7/lib/python3.7/site-packages/flask/app.py", line 1952, in full_dispatch_request
    rv = self.handle_user_exception(e)
  File "/Library/Frameworks/Python.framework/Versions/3.7/lib/python3.7/site-packages/flask/app.py", line 1821, in handle_user_exception
    reraise(exc_type, exc_value, tb)
  File "/Library/Frameworks/Python.framework/Versions/3.7/lib/python3.7/site-packages/flask/_compat.py", line 39, in reraise
    raise value
  File "/Library/Frameworks/Python.framework/Versions/3.7/lib/python3.7/site-packages/flask/app.py", line 1950, in full_dispatch_request
    rv = self.dispatch_request()
  File "/Library/Frameworks/Python.framework/Versions/3.7/lib/python3.7/site-packages/flask/app.py", line 1936, in dispatch_request
    return self.view_functions[rule.endpoint](**req.view_args)
  File "app.py", line 228, in artists
    artist_query = db.session.query(Artist).all()
  File "/Library/Frameworks/Python.framework/Versions/3.7/lib/python3.7/site-packages/sqlalchemy/orm/scoping.py", line 162, in do
    return getattr(self.registry(), name)(*args, **kwargs)
  File "/Library/Frameworks/Python.framework/Versions/3.7/lib/python3.7/site-packages/sqlalchemy/util/_collections.py", line 1032, in __call__
    return self.registry.setdefault(key, self.createfunc())
  File "/Library/Frameworks/Python.framework/Versions/3.7/lib/python3.7/site-packages/sqlalchemy/orm/session.py", line 3254, in __call__
    return self.class_(**local_kw)
  File "/Library/Frameworks/Python.framework/Versions/3.7/lib/python3.7/site-packages/flask_sqlalchemy/__init__.py", line 138, in __init__
    bind = options.pop('bind', None) or db.engine
  File "/Library/Frameworks/Python.framework/Versions/3.7/lib/python3.7/site-packages/flask_sqlalchemy/__init__.py", line 937, in engine
    return self.get_engine()
  File "/Library/Frameworks/Python.framework/Versions/3.7/lib/python3.7/site-packages/flask_sqlalchemy/__init__.py", line 956, in get_engine
    return connector.get_engine()
  File "/Library/Frameworks/Python.framework/Versions/3.7/lib/python3.7/site-packages/flask_sqlalchemy/__init__.py", line 560, in get_engine
    options = self.get_options(sa_url, echo)
  File "/Library/Frameworks/Python.framework/Versions/3.7/lib/python3.7/site-packages/flask_sqlalchemy/__init__.py", line 575, in get_options
    self._sa.apply_driver_hacks(self._app, sa_url, options)
  File "/Library/Frameworks/Python.framework/Versions/3.7/lib/python3.7/site-packages/flask_sqlalchemy/__init__.py", line 877, in apply_driver_hacks
    if sa_url.drivername.startswith('mysql'):
AttributeError: 'NoneType' object has no attribute 'drivername'
2020-05-25 11:26:13,116 INFO: errors [in app.py:464]
2020-05-25 11:26:29,074 ERROR: Exception on /shows [GET] [in /Library/Frameworks/Python.framework/Versions/3.7/lib/python3.7/site-packages/flask/app.py:1892]
Traceback (most recent call last):
  File "/Library/Frameworks/Python.framework/Versions/3.7/lib/python3.7/site-packages/sqlalchemy/util/_collections.py", line 1030, in __call__
    return self.registry[key]
KeyError: 123145450835968

During handling of the above exception, another exception occurred:

Traceback (most recent call last):
  File "/Library/Frameworks/Python.framework/Versions/3.7/lib/python3.7/site-packages/flask/app.py", line 2447, in wsgi_app
    response = self.full_dispatch_request()
  File "/Library/Frameworks/Python.framework/Versions/3.7/lib/python3.7/site-packages/flask/app.py", line 1952, in full_dispatch_request
    rv = self.handle_user_exception(e)
  File "/Library/Frameworks/Python.framework/Versions/3.7/lib/python3.7/site-packages/flask/app.py", line 1821, in handle_user_exception
    reraise(exc_type, exc_value, tb)
  File "/Library/Frameworks/Python.framework/Versions/3.7/lib/python3.7/site-packages/flask/_compat.py", line 39, in reraise
    raise value
  File "/Library/Frameworks/Python.framework/Versions/3.7/lib/python3.7/site-packages/flask/app.py", line 1950, in full_dispatch_request
    rv = self.dispatch_request()
  File "/Library/Frameworks/Python.framework/Versions/3.7/lib/python3.7/site-packages/flask/app.py", line 1936, in dispatch_request
    return self.view_functions[rule.endpoint](**req.view_args)
  File "app.py", line 410, in shows
    shows = Show.query.all()
  File "/Library/Frameworks/Python.framework/Versions/3.7/lib/python3.7/site-packages/flask_sqlalchemy/__init__.py", line 519, in __get__
    return type.query_class(mapper, session=self.sa.session())
  File "/Library/Frameworks/Python.framework/Versions/3.7/lib/python3.7/site-packages/sqlalchemy/orm/scoping.py", line 78, in __call__
    return self.registry()
  File "/Library/Frameworks/Python.framework/Versions/3.7/lib/python3.7/site-packages/sqlalchemy/util/_collections.py", line 1032, in __call__
    return self.registry.setdefault(key, self.createfunc())
  File "/Library/Frameworks/Python.framework/Versions/3.7/lib/python3.7/site-packages/sqlalchemy/orm/session.py", line 3254, in __call__
    return self.class_(**local_kw)
  File "/Library/Frameworks/Python.framework/Versions/3.7/lib/python3.7/site-packages/flask_sqlalchemy/__init__.py", line 138, in __init__
    bind = options.pop('bind', None) or db.engine
  File "/Library/Frameworks/Python.framework/Versions/3.7/lib/python3.7/site-packages/flask_sqlalchemy/__init__.py", line 937, in engine
    return self.get_engine()
  File "/Library/Frameworks/Python.framework/Versions/3.7/lib/python3.7/site-packages/flask_sqlalchemy/__init__.py", line 956, in get_engine
    return connector.get_engine()
  File "/Library/Frameworks/Python.framework/Versions/3.7/lib/python3.7/site-packages/flask_sqlalchemy/__init__.py", line 560, in get_engine
    options = self.get_options(sa_url, echo)
  File "/Library/Frameworks/Python.framework/Versions/3.7/lib/python3.7/site-packages/flask_sqlalchemy/__init__.py", line 575, in get_options
    self._sa.apply_driver_hacks(self._app, sa_url, options)
  File "/Library/Frameworks/Python.framework/Versions/3.7/lib/python3.7/site-packages/flask_sqlalchemy/__init__.py", line 877, in apply_driver_hacks
    if sa_url.drivername.startswith('mysql'):
AttributeError: 'NoneType' object has no attribute 'drivername'
2020-05-25 11:26:30,047 ERROR: Exception on /artists [GET] [in /Library/Frameworks/Python.framework/Versions/3.7/lib/python3.7/site-packages/flask/app.py:1892]
Traceback (most recent call last):
  File "/Library/Frameworks/Python.framework/Versions/3.7/lib/python3.7/site-packages/sqlalchemy/util/_collections.py", line 1030, in __call__
    return self.registry[key]
KeyError: 123145456091136

During handling of the above exception, another exception occurred:

Traceback (most recent call last):
  File "/Library/Frameworks/Python.framework/Versions/3.7/lib/python3.7/site-packages/flask/app.py", line 2447, in wsgi_app
    response = self.full_dispatch_request()
  File "/Library/Frameworks/Python.framework/Versions/3.7/lib/python3.7/site-packages/flask/app.py", line 1952, in full_dispatch_request
    rv = self.handle_user_exception(e)
  File "/Library/Frameworks/Python.framework/Versions/3.7/lib/python3.7/site-packages/flask/app.py", line 1821, in handle_user_exception
    reraise(exc_type, exc_value, tb)
  File "/Library/Frameworks/Python.framework/Versions/3.7/lib/python3.7/site-packages/flask/_compat.py", line 39, in reraise
    raise value
  File "/Library/Frameworks/Python.framework/Versions/3.7/lib/python3.7/site-packages/flask/app.py", line 1950, in full_dispatch_request
    rv = self.dispatch_request()
  File "/Library/Frameworks/Python.framework/Versions/3.7/lib/python3.7/site-packages/flask/app.py", line 1936, in dispatch_request
    return self.view_functions[rule.endpoint](**req.view_args)
  File "app.py", line 228, in artists
    artist_query = db.session.query(Artist).all()
  File "/Library/Frameworks/Python.framework/Versions/3.7/lib/python3.7/site-packages/sqlalchemy/orm/scoping.py", line 162, in do
    return getattr(self.registry(), name)(*args, **kwargs)
  File "/Library/Frameworks/Python.framework/Versions/3.7/lib/python3.7/site-packages/sqlalchemy/util/_collections.py", line 1032, in __call__
    return self.registry.setdefault(key, self.createfunc())
  File "/Library/Frameworks/Python.framework/Versions/3.7/lib/python3.7/site-packages/sqlalchemy/orm/session.py", line 3254, in __call__
    return self.class_(**local_kw)
  File "/Library/Frameworks/Python.framework/Versions/3.7/lib/python3.7/site-packages/flask_sqlalchemy/__init__.py", line 138, in __init__
    bind = options.pop('bind', None) or db.engine
  File "/Library/Frameworks/Python.framework/Versions/3.7/lib/python3.7/site-packages/flask_sqlalchemy/__init__.py", line 937, in engine
    return self.get_engine()
  File "/Library/Frameworks/Python.framework/Versions/3.7/lib/python3.7/site-packages/flask_sqlalchemy/__init__.py", line 956, in get_engine
    return connector.get_engine()
  File "/Library/Frameworks/Python.framework/Versions/3.7/lib/python3.7/site-packages/flask_sqlalchemy/__init__.py", line 560, in get_engine
    options = self.get_options(sa_url, echo)
  File "/Library/Frameworks/Python.framework/Versions/3.7/lib/python3.7/site-packages/flask_sqlalchemy/__init__.py", line 575, in get_options
    self._sa.apply_driver_hacks(self._app, sa_url, options)
  File "/Library/Frameworks/Python.framework/Versions/3.7/lib/python3.7/site-packages/flask_sqlalchemy/__init__.py", line 877, in apply_driver_hacks
    if sa_url.drivername.startswith('mysql'):
AttributeError: 'NoneType' object has no attribute 'drivername'
2020-05-25 11:27:17,266 INFO: errors [in app.py:464]
